[2024-05-18T15:09:04.218+0000] {local_task_job_runner.py:120} INFO - ::group::Pre task execution logs
[2024-05-18T15:09:04.242+0000] {taskinstance.py:2076} INFO - Dependencies all met for dep_context=non-requeueable deps ti=<TaskInstance: dummyjson_ingestion.is_api_available scheduled__2024-05-01T00:00:00+00:00 [queued]>
[2024-05-18T15:09:04.254+0000] {taskinstance.py:2076} INFO - Dependencies all met for dep_context=requeueable deps ti=<TaskInstance: dummyjson_ingestion.is_api_available scheduled__2024-05-01T00:00:00+00:00 [queued]>
[2024-05-18T15:09:04.255+0000] {taskinstance.py:2306} INFO - Starting attempt 1 of 1
[2024-05-18T15:09:04.279+0000] {taskinstance.py:2330} INFO - Executing <Task(HttpSensor): is_api_available> on 2024-05-01 00:00:00+00:00
[2024-05-18T15:09:04.290+0000] {warnings.py:110} WARNING - /home/***/.local/lib/python3.12/site-packages/***/task/task_runner/standard_task_runner.py:61: DeprecationWarning: This process (pid=576) is multi-threaded, use of fork() may lead to deadlocks in the child.
  pid = os.fork()

[2024-05-18T15:09:04.293+0000] {standard_task_runner.py:63} INFO - Started process 580 to run task
[2024-05-18T15:09:04.294+0000] {standard_task_runner.py:90} INFO - Running: ['***', 'tasks', 'run', 'dummyjson_ingestion', 'is_api_available', 'scheduled__2024-05-01T00:00:00+00:00', '--job-id', '1143', '--raw', '--subdir', 'DAGS_FOLDER/weekly_assignment.py', '--cfg-path', '/tmp/tmpa4ea6ji0']
[2024-05-18T15:09:04.298+0000] {standard_task_runner.py:91} INFO - Job 1143: Subtask is_api_available
[2024-05-18T15:09:04.375+0000] {task_command.py:426} INFO - Running <TaskInstance: dummyjson_ingestion.is_api_available scheduled__2024-05-01T00:00:00+00:00 [running]> on host 8d1d9b6df744
[2024-05-18T15:09:04.526+0000] {taskinstance.py:2648} INFO - Exporting env vars: AIRFLOW_CTX_DAG_OWNER='***' AIRFLOW_CTX_DAG_ID='dummyjson_ingestion' AIRFLOW_CTX_TASK_ID='is_api_available' AIRFLOW_CTX_EXECUTION_DATE='2024-05-01T00:00:00+00:00' AIRFLOW_CTX_TRY_NUMBER='1' AIRFLOW_CTX_DAG_RUN_ID='scheduled__2024-05-01T00:00:00+00:00'
[2024-05-18T15:09:04.534+0000] {taskinstance.py:430} INFO - ::endgroup::
[2024-05-18T15:09:04.535+0000] {baseoperator.py:399} WARNING - HttpSensor.execute cannot be called outside TaskInstance!
[2024-05-18T15:09:04.537+0000] {http.py:137} INFO - Poking: /users
[2024-05-18T15:09:04.556+0000] {base.py:84} INFO - Using connection ID 'dummyjson_api' for task execution.
[2024-05-18T15:09:05.533+0000] {http.py:199} ERROR - HTTP error: Not Found
[2024-05-18T15:09:05.536+0000] {http.py:200} ERROR - not found!
[2024-05-18T15:09:59.998+0000] {local_task_job_runner.py:310} WARNING - State of this instance has been externally set to restarting. Terminating instance.
[2024-05-18T15:10:00.000+0000] {local_task_job_runner.py:222} INFO - ::endgroup::
[2024-05-18T15:10:00.006+0000] {process_utils.py:132} INFO - Sending 15 to group 580. PIDs of all processes in the group: [580]
[2024-05-18T15:10:00.007+0000] {process_utils.py:87} INFO - Sending the signal 15 to group 580
[2024-05-18T15:10:00.008+0000] {taskinstance.py:2611} ERROR - Received SIGTERM. Terminating subprocesses.
[2024-05-18T15:10:00.010+0000] {taskinstance.py:441} INFO - ::group::Post task execution logs
[2024-05-18T15:10:00.025+0000] {taskinstance.py:2905} ERROR - Task failed with exception
Traceback (most recent call last):
  File "/home/airflow/.local/lib/python3.12/site-packages/airflow/models/taskinstance.py", line 465, in _execute_task
    result = _execute_callable(context=context, **execute_callable_kwargs)
             ^^^^^^^^^^^^^^^^^^^^^^^^^^^^^^^^^^^^^^^^^^^^^^^^^^^^^^^^^^^^^
  File "/home/airflow/.local/lib/python3.12/site-packages/airflow/models/taskinstance.py", line 432, in _execute_callable
    return execute_callable(context=context, **execute_callable_kwargs)
           ^^^^^^^^^^^^^^^^^^^^^^^^^^^^^^^^^^^^^^^^^^^^^^^^^^^^^^^^^^^^
  File "/home/airflow/.local/lib/python3.12/site-packages/airflow/models/baseoperator.py", line 400, in wrapper
    return func(self, *args, **kwargs)
           ^^^^^^^^^^^^^^^^^^^^^^^^^^^
  File "/home/airflow/.local/lib/python3.12/site-packages/airflow/providers/http/sensors/http.py", line 164, in execute
    super().execute(context=context)
  File "/home/airflow/.local/lib/python3.12/site-packages/airflow/models/baseoperator.py", line 400, in wrapper
    return func(self, *args, **kwargs)
           ^^^^^^^^^^^^^^^^^^^^^^^^^^^
  File "/home/airflow/.local/lib/python3.12/site-packages/airflow/sensors/base.py", line 292, in execute
    time.sleep(self._get_next_poke_interval(started_at, run_duration, try_number))
  File "/home/airflow/.local/lib/python3.12/site-packages/airflow/models/taskinstance.py", line 2613, in signal_handler
    raise AirflowTaskTerminated("Task received SIGTERM signal")
airflow.exceptions.AirflowTaskTerminated: Task received SIGTERM signal
[2024-05-18T15:10:00.037+0000] {taskinstance.py:1206} INFO - Marking task as UP_FOR_RETRY. dag_id=dummyjson_ingestion, task_id=is_api_available, run_id=scheduled__2024-05-01T00:00:00+00:00, execution_date=20240501T000000, start_date=20240518T150904, end_date=20240518T151000
[2024-05-18T15:10:00.101+0000] {process_utils.py:80} INFO - Process psutil.Process(pid=580, status='terminated', exitcode=2, started='15:09:04') (580) terminated with exit code 2
