[2024-05-18T16:43:51.449+0000] {task_context_logger.py:104} ERROR - Executor reports task instance <TaskInstance: dummyjson_ingestion.transform_user manual__2024-05-18T16:38:35.815442+00:00 [queued]> finished (failed) although the task says it's queued. (Info: None) Was the task killed externally?
