[2024-05-19T15:17:48.223+0000] {local_task_job_runner.py:120} INFO - ::group::Pre task execution logs
[2024-05-19T15:17:48.271+0000] {taskinstance.py:2076} INFO - Dependencies all met for dep_context=non-requeueable deps ti=<TaskInstance: dummyjson.write_to_csv_user scheduled__2024-05-17T17:00:00+00:00 [queued]>
[2024-05-19T15:17:48.304+0000] {taskinstance.py:2076} INFO - Dependencies all met for dep_context=requeueable deps ti=<TaskInstance: dummyjson.write_to_csv_user scheduled__2024-05-17T17:00:00+00:00 [queued]>
[2024-05-19T15:17:48.305+0000] {taskinstance.py:2306} INFO - Starting attempt 1 of 6
[2024-05-19T15:17:48.366+0000] {taskinstance.py:2330} INFO - Executing <Task(PythonOperator): write_to_csv_user> on 2024-05-17 17:00:00+00:00
[2024-05-19T15:17:48.384+0000] {warnings.py:110} WARNING - /home/***/.local/lib/python3.12/site-packages/***/task/task_runner/standard_task_runner.py:61: DeprecationWarning: This process (pid=1481) is multi-threaded, use of fork() may lead to deadlocks in the child.
  pid = os.fork()

[2024-05-19T15:17:48.389+0000] {standard_task_runner.py:90} INFO - Running: ['***', 'tasks', 'run', 'dummyjson', 'write_to_csv_user', 'scheduled__2024-05-17T17:00:00+00:00', '--job-id', '1962', '--raw', '--subdir', 'DAGS_FOLDER/dummyjson.py', '--cfg-path', '/tmp/tmp07kr9mo4']
[2024-05-19T15:17:48.393+0000] {standard_task_runner.py:91} INFO - Job 1962: Subtask write_to_csv_user
[2024-05-19T15:17:48.388+0000] {standard_task_runner.py:63} INFO - Started process 1504 to run task
[2024-05-19T15:17:48.574+0000] {task_command.py:426} INFO - Running <TaskInstance: dummyjson.write_to_csv_user scheduled__2024-05-17T17:00:00+00:00 [running]> on host ca927d78a9ea
[2024-05-19T15:17:49.668+0000] {taskinstance.py:2648} INFO - Exporting env vars: AIRFLOW_CTX_DAG_EMAIL='fathurrahmanhernanda@gmail.com' AIRFLOW_CTX_DAG_OWNER='***' AIRFLOW_CTX_DAG_ID='dummyjson' AIRFLOW_CTX_TASK_ID='write_to_csv_user' AIRFLOW_CTX_EXECUTION_DATE='2024-05-17T17:00:00+00:00' AIRFLOW_CTX_TRY_NUMBER='1' AIRFLOW_CTX_DAG_RUN_ID='scheduled__2024-05-17T17:00:00+00:00'
[2024-05-19T15:17:49.678+0000] {taskinstance.py:430} INFO - ::endgroup::
[2024-05-19T15:17:49.740+0000] {taskinstance.py:441} INFO - ::group::Post task execution logs
[2024-05-19T15:17:49.742+0000] {taskinstance.py:2905} ERROR - Task failed with exception
Traceback (most recent call last):
  File "/home/airflow/.local/lib/python3.12/site-packages/airflow/models/taskinstance.py", line 465, in _execute_task
    result = _execute_callable(context=context, **execute_callable_kwargs)
             ^^^^^^^^^^^^^^^^^^^^^^^^^^^^^^^^^^^^^^^^^^^^^^^^^^^^^^^^^^^^^
  File "/home/airflow/.local/lib/python3.12/site-packages/airflow/models/taskinstance.py", line 432, in _execute_callable
    return execute_callable(context=context, **execute_callable_kwargs)
           ^^^^^^^^^^^^^^^^^^^^^^^^^^^^^^^^^^^^^^^^^^^^^^^^^^^^^^^^^^^^
  File "/home/airflow/.local/lib/python3.12/site-packages/airflow/models/baseoperator.py", line 400, in wrapper
    return func(self, *args, **kwargs)
           ^^^^^^^^^^^^^^^^^^^^^^^^^^^
  File "/home/airflow/.local/lib/python3.12/site-packages/airflow/operators/python.py", line 235, in execute
    return_value = self.execute_callable()
                   ^^^^^^^^^^^^^^^^^^^^^^^
  File "/home/airflow/.local/lib/python3.12/site-packages/airflow/operators/python.py", line 252, in execute_callable
    return self.python_callable(*self.op_args, **self.op_kwargs)
           ^^^^^^^^^^^^^^^^^^^^^^^^^^^^^^^^^^^^^^^^^^^^^^^^^^^^^
  File "/opt/airflow/dags/dummyjson.py", line 107, in write_to_csv_generic
    writer.writerows(transformed_data)
  File "/usr/local/lib/python3.12/csv.py", line 167, in writerows
    return self.writer.writerows(map(self._dict_to_list, rowdicts))
           ^^^^^^^^^^^^^^^^^^^^^^^^^^^^^^^^^^^^^^^^^^^^^^^^^^^^^^^^
  File "/usr/local/lib/python3.12/csv.py", line 159, in _dict_to_list
    raise ValueError("dict contains fields not in fieldnames: "
ValueError: dict contains fields not in fieldnames: 'first_name', 'user_id', 'last_name'
[2024-05-19T15:17:49.786+0000] {taskinstance.py:1206} INFO - Marking task as UP_FOR_RETRY. dag_id=dummyjson, task_id=write_to_csv_user, run_id=scheduled__2024-05-17T17:00:00+00:00, execution_date=20240517T170000, start_date=20240519T151748, end_date=20240519T151749
[2024-05-19T15:17:49.823+0000] {standard_task_runner.py:110} ERROR - Failed to execute job 1962 for task write_to_csv_user (dict contains fields not in fieldnames: 'first_name', 'user_id', 'last_name'; 1504)
[2024-05-19T15:17:49.874+0000] {local_task_job_runner.py:240} INFO - Task exited with return code 1
[2024-05-19T15:17:49.935+0000] {taskinstance.py:3498} INFO - 0 downstream tasks scheduled from follow-on schedule check
[2024-05-19T15:17:49.941+0000] {local_task_job_runner.py:222} INFO - ::endgroup::
