[2024-05-19T13:04:23.293+0000] {local_task_job_runner.py:120} INFO - ::group::Pre task execution logs
[2024-05-19T13:04:23.325+0000] {taskinstance.py:2076} INFO - Dependencies all met for dep_context=non-requeueable deps ti=<TaskInstance: extract_products_from_api.load_to_bigquery scheduled__2024-05-01T00:00:00+00:00 [queued]>
[2024-05-19T13:04:23.343+0000] {taskinstance.py:2076} INFO - Dependencies all met for dep_context=requeueable deps ti=<TaskInstance: extract_products_from_api.load_to_bigquery scheduled__2024-05-01T00:00:00+00:00 [queued]>
[2024-05-19T13:04:23.344+0000] {taskinstance.py:2306} INFO - Starting attempt 3 of 4
[2024-05-19T13:04:23.370+0000] {taskinstance.py:2330} INFO - Executing <Task(PythonOperator): load_to_bigquery> on 2024-05-01 00:00:00+00:00
[2024-05-19T13:04:23.381+0000] {warnings.py:110} WARNING - /home/***/.local/lib/python3.12/site-packages/***/task/task_runner/standard_task_runner.py:61: DeprecationWarning: This process (pid=5015) is multi-threaded, use of fork() may lead to deadlocks in the child.
  pid = os.fork()

[2024-05-19T13:04:23.385+0000] {standard_task_runner.py:63} INFO - Started process 5022 to run task
[2024-05-19T13:04:23.389+0000] {standard_task_runner.py:90} INFO - Running: ['***', 'tasks', 'run', 'extract_products_from_api', 'load_to_bigquery', 'scheduled__2024-05-01T00:00:00+00:00', '--job-id', '1841', '--raw', '--subdir', 'DAGS_FOLDER/dummyjson_product.py', '--cfg-path', '/tmp/tmpfr92p1ut']
[2024-05-19T13:04:23.391+0000] {standard_task_runner.py:91} INFO - Job 1841: Subtask load_to_bigquery
[2024-05-19T13:04:23.481+0000] {task_command.py:426} INFO - Running <TaskInstance: extract_products_from_api.load_to_bigquery scheduled__2024-05-01T00:00:00+00:00 [running]> on host ca927d78a9ea
[2024-05-19T13:04:23.685+0000] {taskinstance.py:2648} INFO - Exporting env vars: AIRFLOW_CTX_DAG_EMAIL='your_email@example.com' AIRFLOW_CTX_DAG_OWNER='***' AIRFLOW_CTX_DAG_ID='extract_products_from_api' AIRFLOW_CTX_TASK_ID='load_to_bigquery' AIRFLOW_CTX_EXECUTION_DATE='2024-05-01T00:00:00+00:00' AIRFLOW_CTX_TRY_NUMBER='3' AIRFLOW_CTX_DAG_RUN_ID='scheduled__2024-05-01T00:00:00+00:00'
[2024-05-19T13:04:23.689+0000] {taskinstance.py:430} INFO - ::endgroup::
[2024-05-19T13:04:23.694+0000] {taskinstance.py:441} INFO - ::group::Post task execution logs
[2024-05-19T13:04:23.696+0000] {taskinstance.py:2905} ERROR - Task failed with exception
Traceback (most recent call last):
  File "/home/airflow/.local/lib/python3.12/site-packages/airflow/models/taskinstance.py", line 465, in _execute_task
    result = _execute_callable(context=context, **execute_callable_kwargs)
             ^^^^^^^^^^^^^^^^^^^^^^^^^^^^^^^^^^^^^^^^^^^^^^^^^^^^^^^^^^^^^
  File "/home/airflow/.local/lib/python3.12/site-packages/airflow/models/taskinstance.py", line 432, in _execute_callable
    return execute_callable(context=context, **execute_callable_kwargs)
           ^^^^^^^^^^^^^^^^^^^^^^^^^^^^^^^^^^^^^^^^^^^^^^^^^^^^^^^^^^^^
  File "/home/airflow/.local/lib/python3.12/site-packages/airflow/models/baseoperator.py", line 400, in wrapper
    return func(self, *args, **kwargs)
           ^^^^^^^^^^^^^^^^^^^^^^^^^^^
  File "/home/airflow/.local/lib/python3.12/site-packages/airflow/operators/python.py", line 235, in execute
    return_value = self.execute_callable()
                   ^^^^^^^^^^^^^^^^^^^^^^^
  File "/home/airflow/.local/lib/python3.12/site-packages/airflow/operators/python.py", line 252, in execute_callable
    return self.python_callable(*self.op_args, **self.op_kwargs)
           ^^^^^^^^^^^^^^^^^^^^^^^^^^^^^^^^^^^^^^^^^^^^^^^^^^^^^
  File "/opt/airflow/dags/dummyjson_product.py", line 81, in load_to_bigquery
    return task.execute_callable(context=context)
           ^^^^^^^^^^^^^^^^^^^^^
AttributeError: 'GCSToBigQueryOperator' object has no attribute 'execute_callable'
[2024-05-19T13:04:23.762+0000] {taskinstance.py:1206} INFO - Marking task as UP_FOR_RETRY. dag_id=extract_products_from_api, task_id=load_to_bigquery, run_id=scheduled__2024-05-01T00:00:00+00:00, execution_date=20240501T000000, start_date=20240519T130423, end_date=20240519T130423
[2024-05-19T13:04:23.795+0000] {standard_task_runner.py:110} ERROR - Failed to execute job 1841 for task load_to_bigquery ('GCSToBigQueryOperator' object has no attribute 'execute_callable'; 5022)
[2024-05-19T13:04:23.854+0000] {local_task_job_runner.py:240} INFO - Task exited with return code 1
[2024-05-19T13:04:23.873+0000] {local_task_job_runner.py:222} INFO - ::endgroup::
