[2024-05-18T16:38:50.304+0000] {local_task_job_runner.py:120} INFO - ::group::Pre task execution logs
[2024-05-18T16:38:50.328+0000] {taskinstance.py:2076} INFO - Dependencies all met for dep_context=non-requeueable deps ti=<TaskInstance: dummyjson_ingestion.transform_user manual__2024-05-18T16:33:08.877658+00:00 [queued]>
[2024-05-18T16:38:50.339+0000] {taskinstance.py:2076} INFO - Dependencies all met for dep_context=requeueable deps ti=<TaskInstance: dummyjson_ingestion.transform_user manual__2024-05-18T16:33:08.877658+00:00 [queued]>
[2024-05-18T16:38:50.340+0000] {taskinstance.py:2306} INFO - Starting attempt 2 of 6
[2024-05-18T16:38:50.362+0000] {taskinstance.py:2330} INFO - Executing <Task(PythonOperator): transform_user> on 2024-05-18 16:33:08.877658+00:00
[2024-05-18T16:38:50.373+0000] {warnings.py:110} WARNING - /home/***/.local/lib/python3.12/site-packages/***/task/task_runner/standard_task_runner.py:61: DeprecationWarning: This process (pid=1914) is multi-threaded, use of fork() may lead to deadlocks in the child.
  pid = os.fork()

[2024-05-18T16:38:50.375+0000] {standard_task_runner.py:63} INFO - Started process 1916 to run task
[2024-05-18T16:38:50.375+0000] {standard_task_runner.py:90} INFO - Running: ['***', 'tasks', 'run', 'dummyjson_ingestion', 'transform_user', 'manual__2024-05-18T16:33:08.877658+00:00', '--job-id', '1223', '--raw', '--subdir', 'DAGS_FOLDER/dummyjson_ingestion.py', '--cfg-path', '/tmp/tmplwr4o_gm']
[2024-05-18T16:38:50.378+0000] {standard_task_runner.py:91} INFO - Job 1223: Subtask transform_user
[2024-05-18T16:38:50.437+0000] {task_command.py:426} INFO - Running <TaskInstance: dummyjson_ingestion.transform_user manual__2024-05-18T16:33:08.877658+00:00 [running]> on host 8d1d9b6df744
[2024-05-18T16:38:50.566+0000] {taskinstance.py:2648} INFO - Exporting env vars: AIRFLOW_CTX_DAG_EMAIL='fathurrahmanhernanda@gmail.com' AIRFLOW_CTX_DAG_OWNER='***' AIRFLOW_CTX_DAG_ID='dummyjson_ingestion' AIRFLOW_CTX_TASK_ID='transform_user' AIRFLOW_CTX_EXECUTION_DATE='2024-05-18T16:33:08.877658+00:00' AIRFLOW_CTX_TRY_NUMBER='2' AIRFLOW_CTX_DAG_RUN_ID='manual__2024-05-18T16:33:08.877658+00:00'
[2024-05-18T16:38:50.570+0000] {taskinstance.py:430} INFO - ::endgroup::
[2024-05-18T16:38:50.588+0000] {taskinstance.py:441} INFO - ::group::Post task execution logs
[2024-05-18T16:38:50.589+0000] {taskinstance.py:2905} ERROR - Task failed with exception
Traceback (most recent call last):
  File "/home/airflow/.local/lib/python3.12/site-packages/airflow/models/taskinstance.py", line 465, in _execute_task
    result = _execute_callable(context=context, **execute_callable_kwargs)
             ^^^^^^^^^^^^^^^^^^^^^^^^^^^^^^^^^^^^^^^^^^^^^^^^^^^^^^^^^^^^^
  File "/home/airflow/.local/lib/python3.12/site-packages/airflow/models/taskinstance.py", line 432, in _execute_callable
    return execute_callable(context=context, **execute_callable_kwargs)
           ^^^^^^^^^^^^^^^^^^^^^^^^^^^^^^^^^^^^^^^^^^^^^^^^^^^^^^^^^^^^
  File "/home/airflow/.local/lib/python3.12/site-packages/airflow/models/baseoperator.py", line 400, in wrapper
    return func(self, *args, **kwargs)
           ^^^^^^^^^^^^^^^^^^^^^^^^^^^
  File "/home/airflow/.local/lib/python3.12/site-packages/airflow/operators/python.py", line 235, in execute
    return_value = self.execute_callable()
                   ^^^^^^^^^^^^^^^^^^^^^^^
  File "/home/airflow/.local/lib/python3.12/site-packages/airflow/operators/python.py", line 252, in execute_callable
    return self.python_callable(*self.op_args, **self.op_kwargs)
           ^^^^^^^^^^^^^^^^^^^^^^^^^^^^^^^^^^^^^^^^^^^^^^^^^^^^^
  File "/opt/airflow/dags/dummyjson_ingestion.py", line 28, in transform_user
    user = response['users']
           ~~~~~~~~^^^^^^^^^
KeyError: 'users'
[2024-05-18T16:38:50.607+0000] {taskinstance.py:1206} INFO - Marking task as UP_FOR_RETRY. dag_id=dummyjson_ingestion, task_id=transform_user, run_id=manual__2024-05-18T16:33:08.877658+00:00, execution_date=20240518T163308, start_date=20240518T163850, end_date=20240518T163850
[2024-05-18T16:38:50.627+0000] {standard_task_runner.py:110} ERROR - Failed to execute job 1223 for task transform_user ('users'; 1916)
[2024-05-18T16:38:50.671+0000] {local_task_job_runner.py:240} INFO - Task exited with return code 1
[2024-05-18T16:38:50.696+0000] {taskinstance.py:3498} INFO - 0 downstream tasks scheduled from follow-on schedule check
[2024-05-18T16:38:50.700+0000] {local_task_job_runner.py:222} INFO - ::endgroup::
