[2024-05-18T16:51:05.064+0000] {local_task_job_runner.py:120} INFO - ::group::Pre task execution logs
[2024-05-18T16:51:05.088+0000] {taskinstance.py:2076} INFO - Dependencies all met for dep_context=non-requeueable deps ti=<TaskInstance: dummyjson_ingestion.transform_user manual__2024-05-18T16:40:48.354328+00:00 [queued]>
[2024-05-18T16:51:05.102+0000] {taskinstance.py:2076} INFO - Dependencies all met for dep_context=requeueable deps ti=<TaskInstance: dummyjson_ingestion.transform_user manual__2024-05-18T16:40:48.354328+00:00 [queued]>
[2024-05-18T16:51:05.103+0000] {taskinstance.py:2306} INFO - Starting attempt 3 of 6
[2024-05-18T16:51:05.124+0000] {taskinstance.py:2330} INFO - Executing <Task(PythonOperator): transform_user> on 2024-05-18 16:40:48.354328+00:00
[2024-05-18T16:51:05.135+0000] {warnings.py:110} WARNING - /home/***/.local/lib/python3.12/site-packages/***/task/task_runner/standard_task_runner.py:61: DeprecationWarning: This process (pid=2104) is multi-threaded, use of fork() may lead to deadlocks in the child.
  pid = os.fork()

[2024-05-18T16:51:05.137+0000] {standard_task_runner.py:63} INFO - Started process 2106 to run task
[2024-05-18T16:51:05.139+0000] {standard_task_runner.py:90} INFO - Running: ['***', 'tasks', 'run', 'dummyjson_ingestion', 'transform_user', 'manual__2024-05-18T16:40:48.354328+00:00', '--job-id', '1235', '--raw', '--subdir', 'DAGS_FOLDER/dummyjson_ingestion.py', '--cfg-path', '/tmp/tmpjqdjzl4l']
[2024-05-18T16:51:05.142+0000] {standard_task_runner.py:91} INFO - Job 1235: Subtask transform_user
[2024-05-18T16:51:05.203+0000] {task_command.py:426} INFO - Running <TaskInstance: dummyjson_ingestion.transform_user manual__2024-05-18T16:40:48.354328+00:00 [running]> on host 8d1d9b6df744
[2024-05-18T16:51:05.334+0000] {taskinstance.py:2648} INFO - Exporting env vars: AIRFLOW_CTX_DAG_EMAIL='fathurrahmanhernanda@gmail.com' AIRFLOW_CTX_DAG_OWNER='***' AIRFLOW_CTX_DAG_ID='dummyjson_ingestion' AIRFLOW_CTX_TASK_ID='transform_user' AIRFLOW_CTX_EXECUTION_DATE='2024-05-18T16:40:48.354328+00:00' AIRFLOW_CTX_TRY_NUMBER='3' AIRFLOW_CTX_DAG_RUN_ID='manual__2024-05-18T16:40:48.354328+00:00'
[2024-05-18T16:51:05.337+0000] {taskinstance.py:430} INFO - ::endgroup::
[2024-05-18T16:51:05.351+0000] {taskinstance.py:441} INFO - ::group::Post task execution logs
[2024-05-18T16:51:05.352+0000] {taskinstance.py:2905} ERROR - Task failed with exception
Traceback (most recent call last):
  File "/home/airflow/.local/lib/python3.12/site-packages/airflow/models/taskinstance.py", line 465, in _execute_task
    result = _execute_callable(context=context, **execute_callable_kwargs)
             ^^^^^^^^^^^^^^^^^^^^^^^^^^^^^^^^^^^^^^^^^^^^^^^^^^^^^^^^^^^^^
  File "/home/airflow/.local/lib/python3.12/site-packages/airflow/models/taskinstance.py", line 432, in _execute_callable
    return execute_callable(context=context, **execute_callable_kwargs)
           ^^^^^^^^^^^^^^^^^^^^^^^^^^^^^^^^^^^^^^^^^^^^^^^^^^^^^^^^^^^^
  File "/home/airflow/.local/lib/python3.12/site-packages/airflow/models/baseoperator.py", line 400, in wrapper
    return func(self, *args, **kwargs)
           ^^^^^^^^^^^^^^^^^^^^^^^^^^^
  File "/home/airflow/.local/lib/python3.12/site-packages/airflow/operators/python.py", line 235, in execute
    return_value = self.execute_callable()
                   ^^^^^^^^^^^^^^^^^^^^^^^
  File "/home/airflow/.local/lib/python3.12/site-packages/airflow/operators/python.py", line 252, in execute_callable
    return self.python_callable(*self.op_args, **self.op_kwargs)
           ^^^^^^^^^^^^^^^^^^^^^^^^^^^^^^^^^^^^^^^^^^^^^^^^^^^^^
  File "/opt/airflow/dags/dummyjson_ingestion.py", line 22, in transform_user
    users = response['users']
            ~~~~~~~~^^^^^^^^^
KeyError: 'users'
[2024-05-18T16:51:05.371+0000] {taskinstance.py:1206} INFO - Marking task as UP_FOR_RETRY. dag_id=dummyjson_ingestion, task_id=transform_user, run_id=manual__2024-05-18T16:40:48.354328+00:00, execution_date=20240518T164048, start_date=20240518T165105, end_date=20240518T165105
[2024-05-18T16:51:05.386+0000] {standard_task_runner.py:110} ERROR - Failed to execute job 1235 for task transform_user ('users'; 2106)
[2024-05-18T16:51:05.433+0000] {local_task_job_runner.py:240} INFO - Task exited with return code 1
[2024-05-18T16:51:05.465+0000] {taskinstance.py:3498} INFO - 0 downstream tasks scheduled from follow-on schedule check
[2024-05-18T16:51:05.469+0000] {local_task_job_runner.py:222} INFO - ::endgroup::
