[2024-05-19T10:12:37.929+0000] {task_context_logger.py:104} ERROR - Executor reports task instance <TaskInstance: dummyjson.is_cart_api_available scheduled__2024-05-01T00:00:00+00:00 [queued]> finished (failed) although the task says it's queued. (Info: None) Was the task killed externally?
